Workbook

Sheet Dataset 1
B1: China Global Investment Tracker
B2: © Data compiled by The American Enterprise Institute and The Heritage Foundation. All rights reserved.
B4: Dataset 1 Investments
B6: Year | C6: Month | D6: Investor | E6: Quantity in Millions | F6: Share Size | G6: Transaction Party | H6: Sector | I6: Subsector | J6: Country | K6: Region | L6: BRI | M6: Greenfield
A7: =ROW()-6 -> 1 | B7: 2005 | C7: January | D7: Chinese Academy of Sciences | E7: 1740 | G7: IBM | H7: Technology | J7: USA | K7: USA
A8: =ROW()-6 -> 2 | B8: 2005 | C8: January | D8: Minmetals | E8: 500 | G8: Cubapetroleo | H8: Metals | J8: Cuba | K8: North America | M8: G
A9: =ROW()-6 -> 3 | B9: 2005 | C9: March | D9: MCC | E9: 670 | F9: 0.85 | G9: Highlands Pacific | H9: Metals | I9: Steel | J9: Papua New Guinea | K9: East Asia | M9: G
A10: =ROW()-6 -> 4 | B10: 2005 | C10: April | D10: China National Off-shore Oil (CNOOC) | E10: 130 | F10: 0.17 | G10: MEG Energy | H10: Energy | I10: Oil | J10: Canada | K10: North America
A11: =ROW()-6 -> 5 | B11: 2005 | C11: June | D11: China Petroleum and Chemical (Sinopec) | E11: 120 | F11: 0.4 | G11: Synenco | H11: Energy | I11: Oil | J11: Canada | K11: North America | M11: G
A12: =ROW()-6 -> 6 | B12: 2005 | C12: July | D12: Jiangsu Yuejin | E12: 100 | F12: 1 | G12: MG | H12: Transport | I12: Autos | J12: Britain | K12: Europe
A13: =ROW()-6 -> 7 | B13: 2005 | C13: July | D13: Sinohydro | E13: 280 | H13: Energy | I13: Hydro | J13: Cambodia | K13: East Asia | M13: G
A14: =ROW()-6 -> 8 | B14: 2005 | C14: August | D14: China National Petroleum Corp. (CNPC) | E14: 4200 | F14: 0.67 | G14: PetroKazakhstan | H14: Energy | I14: Oil | J14: Kazakhstan | K14: West Asia
A15: =ROW()-6 -> 9 | B15: 2005 | C15: September | D15: China National Petroleum Corp. (CNPC), China Petroleum and Chemical (Sinopec) | E15: 1420 | G15: EnCana | H15: Energy | I15: Oil | J15: Ecuador | K15: South America
A16: =ROW()-6 -> 10 | B16: 2005 | C16: September | D16: China Investment Corporation (CIC), Beijing Jingdeshun | E16: 200 | H16: Energy | I16: Oil | J16: Mongolia | K16: East Asia | M16: G
A17: =ROW()-6 -> 11 | B17: 2005 | C17: October | D17: Sinosteel | E17: 140 | F17: 0.5 | G17: Midwest | H17: Metals | I17: Steel | J17: Australia | K17: Australia | M17: G
A18: =ROW()-6 -> 12 | B18: 2005 | C18: October | D18: China National Chemical (ChemChina) | E18: 180 | F18: 1 | G18: Qenos | H18: Chemicals | J18: Australia | K18: Australia
A19: =ROW()-6 -> 13 | B19: 2005 | C19: December | D19: China National Petroleum Corp. (CNPC) | E19: 290 | F19: 0.16 | G19: Petro-Canada | H19: Energy | I19: Oil | J19: Syria | K19: Arab Middle East and North Africa
A20: =ROW()-6 -> 14 | B20: 2005 | C20: December | D20: Zhejiang Holley | E20: 150 | F20: 0.75 | G20: Amata | H20: Other | I20: Industry | J20: Thailand | K20: East Asia | M20: G
A21: =ROW()-6 -> 15 | B21: 2006 | C21: January | D21: China National Off-shore Oil (CNOOC) | E21: 2270 | F21: 0.45 | G21: South African Petroleum | H21: Energy | J21: Nigeria | K21: Sub-Saharan Africa
A22: =ROW()-6 -> 16 | B22: 2006 | C22: January | D22: China National Chemical (ChemChina) | E22: 480 | F22: 1 | G22: Adisseo | H22: Agriculture | J22: France | K22: Europe
A23: =ROW()-6 -> 17 | B23: 2006 | C23: January | D23: China National Petroleum Corp. (CNPC) | E23: 480 | F23: 1 | H23: Energy | I23: Oil | J23: Chad | K23: Sub-Saharan Africa
A24: =ROW()-6 -> 18 | B24: 2006 | C24: March | D24: China International Trust and Investment (CITIC) | E24: 2920 | G24: Mineralogy | H24: Metals | I24: Steel | J24: Australia | K24: Australia | M24: G
A25: =ROW()-6 -> 19 | B25: 2006 | C25: April | D25: Shanghai Municipal Government | E25: 1300 | F25: 1 | H25: Real estate | I25: Property | J25: Russian Federation | K25: West Asia | M25: G
A26: =ROW()-6 -> 20 | B26: 2006 | C26: May | D26: MCC | E26: 120 | F26: 1 | H26: Other | I26: Timber | J26: Russian Federation | K26: West Asia | M26: G
A27: =ROW()-6 -> 21 | B27: 2006 | C27: May | D27: China Petroleum and Chemical (Sinopec) | E27: 740 | F27: 0.75 | G27: Sonangol | H27: Energy | I27: Oil | J27: Angola | K27: Sub-Saharan Africa | M27: G
A28: =ROW()-6 -> 22 | B28: 2006 | C28: June | D28: China Petroleum and Chemical (Sinopec) | E28: 3490 | F28: 0.49 | G28: Rosneft | H28: Energy | J28: Russian Federation | K28: West Asia
A29: =ROW()-6 -> 23 | B29: 2006 | C29: July | D29: China International Trust and Investment (CITIC) | E29: 100 | F29: 0.51 | G29: Kuwait Petroleum | H29: Energy | I29: Oil | J29: Indonesia | K29: East Asia
A30: =ROW()-6 -> 24 | B30: 2006 | C30: July | D30: China National Petroleum Corp. (CNPC) | E30: 500 | G30: Rosneft | H30: Energy | J30: Russian Federation | K30: West Asia
A31: =ROW()-6 -> 25 | B31: 2006 | C31: August | D31: Wuxi Suntech | E31: 110 | F31: 0.67 | G31: MSK | H31: Energy | I31: Alternative | J31: Japan | K31: East Asia
A32: =ROW()-6 -> 26 | B32: 2006 | C32: September | D32: China Petroleum and Chemical (Sinopec) | E32: 430 | F32: 0.5 | G32: Omimex | H32: Energy | I32: Oil | J32: Colombia | K32: South America
A33: =ROW()-6 -> 27 | B33: 2006 | C33: October | D33: Jiangxi Copper | E33: 110 | F33: 0.75 | G33: bcMetals | H33: Metals | I33: Copper | J33: Canada | K33: North America | M33: G
A34: =ROW()-6 -> 28 | B34: 2006 | C34: October | D34: China International Trust and Investment (CITIC), Aluminum Corporation of China (Chinalco) | E34: 940 | H34: Metals | I34: Aluminum | J34: Egypt | K34: Arab Middle East and North Africa | M34: G
A35: =ROW()-6 -> 29 | B35: 2006 | C35: October | D35: China International Trust and Investment (CITIC) | E35: 1910 | G35: Nations Energy | H35: Energy | J35: Kazakhstan | K35: West Asia
A36: =ROW()-6 -> 30 | B36: 2006 | C36: November | D36: China Development Bank | E36: 800 | F36: 0.01 | G36: Anglo-American | H36: Metals | J36: Britain | K36: Europe
A37: =ROW()-6 -> 31 | B37: 2006 | C37: November | D37: Sinosteel | E37: 230 | F37: 0.5 | G37: Samancor Chrome | H37: Metals | I37: Steel | J37: South Africa | K37: Sub-Saharan Africa
A38: =ROW()-6 -> 32 | B38: 2006 | C38: November | D38: China Nonferrous | E38: 310 | F38: 1 | H38: Metals | I38: Copper | J38: Zambia | K38: Sub-Saharan Africa | M38: G
A39: =ROW()-6 -> 33 | B39: 2006 | C39: November | D39: Ex-Im Bank | E39: 1160 | H39: Metals | J39: Democratic Republic of the Congo | K39: Sub-Saharan Africa
A40: =ROW()-6 -> 34 | B40: 2006 | C40: November | D40: Three Gorges | E40: 140 | F40: 0.9 | G40: EDL | H40: Energy | I40: Hydro | J40: Laos | K40: East Asia | M40: G
A41: =ROW()-6 -> 35 | B41: 2006 | C41: December | D41: Bank of China | E41: 970 | F41: 1 | G41: WestLB, Singapore Air, local government | H41: Transport | I41: Aviation | J41: Singapore | K41: East Asia
A42: =ROW()-6 -> 36 | B42: 2006 | C42: December | D42: Sichuan Changhong | E42: 100 | F42: 0.75 | G42: Sterope investments | H42: Finance | I42: Investment | J42: Netherlands | K42: Europe
...

Sheet Dataset 2
B1: China Global Investment Tracker
B2: © Data compiled by The American Enterprise Institute and The Heritage Foundation. All rights reserved.
B4: Dataset 2 Construction
B6: Year | C6: Month | D6: Contractor | E6: Quantity in Millions | F6: Share Size | G6: Transaction Party | H6: Sector | I6: Subsector | J6: Country | K6: Region | L6: BRI
A7: =ROW()-6 -> 1 | B7: 2005 | C7: January | D7: Sinohydro | E7: 100 | H7: Transport | I7: Aviation | J7: Qatar | K7: Arab Middle East and North Africa
A8: =ROW()-6 -> 2 | B8: 2005 | C8: February | D8: Sinohydro | E8: 150 | G8: Oman Wastewater Services | H8: Utilities | J8: Oman | K8: Arab Middle East and North Africa
A9: =ROW()-6 -> 3 | B9: 2005 | C9: February | D9: Sinohydro | E9: 370 | H9: Transport | I9: Autos | J9: Ecuador | K9: South America
A10: =ROW()-6 -> 4 | B10: 2005 | C10: March | D10: Sinoma | E10: 170 | G10: Riyadh Cement | H10: Real estate | I10: Construction | J10: Saudi Arabia | K10: Arab Middle East and North Africa
A11: =ROW()-6 -> 5 | B11: 2005 | C11: April | D11: China National Machinery Industry (Sinomach) | E11: 100 | H11: Utilities | J11: Sudan | K11: Arab Middle East and North Africa
A12: =ROW()-6 -> 6 | B12: 2005 | C12: April | D12: Minmetals, MCC | E12: 240 | H12: Metals | I12: Steel | J12: Brazil | K12: South America
A13: =ROW()-6 -> 7 | B13: 2005 | C13: May | D13: China National Petroleum Corp. (CNPC) | E13: 390 | G13: SONATRACH | H13: Energy | J13: Algeria | K13: Arab Middle East and North Africa
A14: =ROW()-6 -> 8 | B14: 2005 | C14: June | D14: China Railway Construction, China General Technology (Genertec) | E14: 1270 | G14: Cengiz and IC Ictas | H14: Transport | I14: Rail | J14: Turkey | K14: West Asia
A15: =ROW()-6 -> 9 | B15: 2005 | C15: June | D15: China National Machinery Industry (Sinomach), Sinohydro | E15: 860 | H15: Energy | I15: Coal | J15: Indonesia | K15: East Asia
A16: =ROW()-6 -> 10 | B16: 2005 | C16: June | D16: MCC | E16: 170 | H16: Transport | I16: Aviation | J16: Mauritania | K16: Arab Middle East and North Africa
A17: =ROW()-6 -> 11 | B17: 2005 | C17: July | D17: China International Trust and Investment (CITIC), Sinohydro | E17: 130 | H17: Energy | I17: Hydro | J17: Myanmar | K17: East Asia
A18: =ROW()-6 -> 12 | B18: 2005 | C18: September | D18: China Petroleum and Chemical (Sinopec) | E18: 350 | F18: 0.45 | G18: Aker Kvaerner | H18: Chemicals | J18: Saudi Arabia | K18: Arab Middle East and North Africa
A19: =ROW()-6 -> 13 | B19: 2005 | C19: October | D19: China Nonferrous | E19: 330 | G19: Kazakhstan Aluminum | H19: Metals | I19: Aluminum | J19: Kazakhstan | K19: West Asia
A20: =ROW()-6 -> 14 | B20: 2005 | C20: October | D20: China Communications Construction | E20: 200 | H20: Transport | I20: Autos | J20: Indonesia | K20: East Asia
A21: =ROW()-6 -> 15 | B21: 2005 | C21: November | D21: China North Industries (Norinco) | E21: 120 | G21: Electricite du Laos | H21: Energy | I21: Hydro | J21: Laos | K21: East Asia
A22: =ROW()-6 -> 16 | B22: 2005 | C22: November | D22: China International Trust and Investment (CITIC) | E22: 1190 | H22: Real estate | I22: Construction | J22: Venezuela | K22: South America
A23: =ROW()-6 -> 17 | B23: 2005 | C23: December | D23: China International Trust and Investment (CITIC), Aluminum Corporation of China (Chinalco) | E23: 900 | G23: South Iran Aluminum | H23: Metals | I23: Aluminum | J23: Iran | K23: West Asia
A24: =ROW()-6 -> 18 | B24: 2005 | C24: December | D24: Sinoma | E24: 580 | G24: Saudi Cement | H24: Real estate | I24: Construction | J24: Saudi Arabia | K24: Arab Middle East and North Africa
A25: =ROW()-6 -> 19 | B25: 2005 | C25: December | D25: China International Trust and Investment (CITIC) | E25: 430 | G25: Brazil Power | H25: Energy | I25: Coal | J25: Brazil | K25: South America
A26: =ROW()-6 -> 20 | B26: 2005 | C26: December | D26: Sinohydro | E26: 210 | H26: Agriculture | J26: Algeria | K26: Arab Middle East and North Africa
A27: =ROW()-6 -> 21 | B27: 2005 | C27: December | D27: China Communications Construction | E27: 210 | H27: Transport | I27: Autos | J27: Angola | K27: Sub-Saharan Africa
A28: =ROW()-6 -> 22 | B28: 2005 | C28: December | D28: China National Nuclear | E28: 860 | H28: Energy | J28: Pakistan | K28: West Asia
A29: =ROW()-6 -> 23 | B29: 2006 | C29: January | D29: State Construction Engineering | E29: 300 | G29: Dubai Properties | H29: Real estate | I29: Construction | J29: UAE | K29: Arab Middle East and North Africa
A30: =ROW()-6 -> 24 | B30: 2006 | C30: January | D30: China North Industries (Norinco) | E30: 310 | G30: Tehran Rail | H30: Transport | I30: Rail | J30: Iran | K30: West Asia
A31: =ROW()-6 -> 25 | B31: 2006 | C31: February | D31: Sinohydro | E31: 540 | H31: Real estate | I31: Construction | J31: Qatar | K31: Arab Middle East and North Africa
A32: =ROW()-6 -> 26 | B32: 2006 | C32: March | D32: China National Machinery Industry (Sinomach) | E32: 460 | H32: Energy | I32: Coal | J32: Sri Lanka | K32: West Asia
A33: =ROW()-6 -> 27 | B33: 2006 | C33: April | D33: China Petroleum and Chemical (Sinopec) | E33: 1290 | G33: Petrobras | H33: Energy | I33: Gas | J33: Brazil | K33: South America
A34: =ROW()-6 -> 28 | B34: 2006 | C34: May | D34: China International Trust and Investment (CITIC), China Railway Construction | E34: 6250 | H34: Transport | I34: Autos | J34: Algeria | K34: Arab Middle East and North Africa
A35: =ROW()-6 -> 29 | B35: 2006 | C35: May | D35: Shandong Electric Power Construction III | E35: 1500 | G35: Vedanta | H35: Energy | I35: Coal | J35: India | K35: West Asia
A36: =ROW()-6 -> 30 | B36: 2006 | C36: May | D36: China Power Engineering Consulting | E36: 110 | H36: Energy | J36: Nigeria | K36: Sub-Saharan Africa
A37: =ROW()-6 -> 31 | B37: 2006 | C37: June | D37: Tebian Electric Apparatus (TBEA) | E37: 400 | H37: Energy | J37: Tajikistan | K37: West Asia
A38: =ROW()-6 -> 32 | B38: 2006 | C38: June | D38: Weihai International Economic | E38: 160 | H38: Transport | I38: Aviation | J38: Congo | K38: Sub-Saharan Africa
A39: =ROW()-6 -> 33 | B39: 2006 | C39: June | D39: Sinoma | E39: 260 | G39: Arab Yemen Cement | H39: Real estate | I39: Construction | J39: Yemen | K39: Arab Middle East and North Africa
A40: =ROW()-6 -> 34 | B40: 2006 | C40: June | D40: Jiangsu International Cooperation Corp | E40: 170 | H40: Utilities | J40: Botswana | K40: Sub-Saharan Africa
A41: =ROW()-6 -> 35 | B41: 2006 | C41: July | D41: China Communications Construction | E41: 300 | H41: Transport | I41: Autos | J41: Tajikistan | K41: West Asia
A42: =ROW()-6 -> 36 | B42: 2006 | C42: July | D42: State Construction Engineering | E42: 260 | H42: Transport | I42: Aviation | J42: Algeria | K42: Arab Middle East and North Africa
...

Sheet Dataset 3
B1: China Global Investment Tracker
B2: © Data compiled by The American Enterprise Institute and The Heritage Foundation. All rights reserved.
B4: Dataset 3 Troubled Transactions
B6: Year | C6: Month | D6: Chinese Entity | E6: Quantity in Millions | F6: Transaction Party | G6: Sector | H6: Subsector | I6: Country | J6: Region | K6: Greenfield | L6: BRI
A7: =ROW()-6 -> 1 | B7: 2005 | C7: July | D7: China National Off-shore Oil (CNOOC) | E7: 18000 | F7: Unocal | G7: Energy | I7: USA | J7: USA
A8: =ROW()-6 -> 2 | B8: 2006 | C8: July | D8: China Mobile | E8: 5300 | F8: Millicom | G8: Technology | H8: Telecom | I8: Luxembourg | J8: Europe
A9: =ROW()-6 -> 3 | B9: 2006 | C9: July | D9: China National Petroleum Corp. (CNPC) | E9: 2500 | F9: Rosneft | G9: Energy | H9: Gas | I9: Russian Federation | J9: West Asia
A10: =ROW()-6 -> 4 | B10: 2006 | C10: July | D10: China National Petroleum Corp. (CNPC) | E10: 1390 | F10: KazMunaiGaz | G10: Energy | H10: Gas | I10: Kazakhstan | J10: West Asia
A11: =ROW()-6 -> 5 | B11: 2006 | C11: July | D11: China Ocean Shipping (COSCO) | E11: 140 | F11: Burg | G11: Transport | H11: Shipping | I11: Netherlands | J11: Europe
A12: =ROW()-6 -> 6 | B12: 2006 | C12: September | D12: China National Off-shore Oil (CNOOC) | E12: 16000 | G12: Energy | H12: Gas | I12: Iran | J12: West Asia | K12: G
A13: =ROW()-6 -> 7 | B13: 2006 | C13: October | D13: Southern Power Grid | E13: 190 | G13: Energy | H13: Hydro | I13: Cambodia | J13: East Asia
A14: =ROW()-6 -> 8 | B14: 2006 | C14: November | D14: China Railway Construction | E14: 7450 | G14: Transport | H14: Rail | I14: Nigeria | J14: Sub-Saharan Africa
A15: =ROW()-6 -> 9 | B15: 2006 | C15: November | D15: Aluminum Corporation of China (Chinalco) | E15: 790 | F15: Vietnam National Coal-Mineral Industries | G15: Metals | H15: Aluminum | I15: Vietnam | J15: East Asia | K15: G
A16: =ROW()-6 -> 10 | B16: 2006 | C16: December | D16: Jinchuan Group | E16: 1000 | F16: Philnico | G16: Metals | H16: Steel | I16: Philippines | J16: East Asia | K16: G
A17: =ROW()-6 -> 11 | B17: 2007 | C17: January | D17: Minmetals | E17: 500 | G17: Metals | I17: Cuba | J17: North America
A18: =ROW()-6 -> 12 | B18: 2007 | C18: March | D18: China Petroleum and Chemical (Sinopec) | E18: 3400 | F18: Sonangol | G18: Energy | H18: Oil | I18: Angola | J18: Sub-Saharan Africa | K18: G
A19: =ROW()-6 -> 13 | B19: 2007 | C19: April | D19: China Petroleum and Chemical (Sinopec) | E19: 110 | F19: Uzbekneftegas | G19: Energy | H19: Oil | I19: Uzbekistan | J19: West Asia
A20: =ROW()-6 -> 14 | B20: 2007 | C20: April | D20: Gezhouba | E20: 1440 | G20: Energy | H20: Hydro | I20: Nigeria | J20: Sub-Saharan Africa
A21: =ROW()-6 -> 15 | B21: 2007 | C21: April | D21: China Merchants | E21: 1000 | G21: Logistics | I21: Vietnam | J21: East Asia
A22: =ROW()-6 -> 16 | B22: 2007 | C22: May | D22: TCL | E22: 300 | F22: Thomson | G22: Technology | I22: France | J22: Europe
A23: =ROW()-6 -> 17 | B23: 2007 | C23: June | D23: China National Off-shore Oil (CNOOC) | E23: 370 | F23: Talisman Energy | G23: Energy | H23: Gas | I23: Indonesia | J23: East Asia
A24: =ROW()-6 -> 18 | B24: 2007 | C24: September | D24: China Development Bank, Jilin Fuhua Agricultural Science and Technology Development | E24: 4130 | G24: Agriculture | I24: Philippines | J24: East Asia | K24: G
A25: =ROW()-6 -> 19 | B25: 2007 | C25: September | D25: Tianye Auto, Chamco | E25: 300 | G25: Transport | H25: Autos | I25: Mexico | J25: North America | K25: G
A26: =ROW()-6 -> 20 | B26: 2007 | C26: October | D26: China Development Bank | E26: 980 | F26: Barclays | G26: Finance | H26: Banking | I26: Britain | J26: Europe
A27: =ROW()-6 -> 21 | B27: 2007 | C27: November | D27: Perfect Field | E27: 1750 | F27: Rowsley | G27: Energy | H27: Alternative | I27: Singapore | J27: East Asia
A28: =ROW()-6 -> 22 | B28: 2007 | C28: November | D28: MCC, Jiangxi Copper | E28: 2520 | G28: Metals | H28: Copper | I28: Afghanistan | J28: West Asia | K28: G
A29: =ROW()-6 -> 23 | B29: 2007 | C29: December | D29: China National Chemical (ChemChina) | E29: 1310 | F29: Nufarm | G29: Agriculture | I29: Australia | J29: Australia
A30: =ROW()-6 -> 24 | B30: 2008 | C30: January | D30: China Development Bank | E30: 2000 | F30: Citigroup | G30: Finance | H30: Banking | I30: USA | J30: USA
A31: =ROW()-6 -> 25 | B31: 2008 | C31: February | D31: ZTE (Zhongxing Telecommunications Equipment) | E31: 300 | G31: Technology | H31: Telecom | I31: Philippines | J31: East Asia
A32: =ROW()-6 -> 26 | B32: 2008 | C32: March | D32: Huawei | E32: 600 | F32: 3Com | G32: Technology | H32: Telecom | I32: USA | J32: USA
A33: =ROW()-6 -> 27 | B33: 2008 | C33: March | D33: China International Trust and Investment (CITIC) | E33: 1000 | F33: Bear Stearns | G33: Finance | H33: Investment | I33: USA | J33: USA
A34: =ROW()-6 -> 28 | B34: 2008 | C34: April | D34: Great Wall Technology | E34: 300 | F34: Iomega | G34: Technology | I34: USA | J34: USA
A35: =ROW()-6 -> 29 | B35: 2008 | C35: April | D35: Shougang Group | E35: 360 | F35: Mt. Gibson | G35: Metals | H35: Steel | I35: Australia | J35: Australia
A36: =ROW()-6 -> 30 | B36: 2008 | C36: September | D36: State Administration of Foreign Exchange (SAFE) | E36: 100 | F36: TPG | G36: Finance | H36: Banking | I36: USA | J36: USA
A37: =ROW()-6 -> 31 | B37: 2008 | C37: September | D37: China Development Bank | E37: 13900 | F37: Dresdner Bank | G37: Finance | H37: Banking | I37: Germany | J37: Europe
A38: =ROW()-6 -> 32 | B38: 2008 | C38: September | D38: Minmetals | E38: 1450 | F38: Codelco | G38: Metals | H38: Copper | I38: Chile | J38: South America
A39: =ROW()-6 -> 33 | B39: 2008 | C39: September | D39: Ping An | E39: 3000 | F39: Fortis | G39: Finance | I39: Belgium | J39: Europe
A40: =ROW()-6 -> 34 | B40: 2008 | C40: September | D40: Shandong Energy | E40: 1210 | F40: Linc Energy | G40: Energy | H40: Coal | I40: Australia | J40: Australia | K40: G
A41: =ROW()-6 -> 35 | B41: 2008 | C41: November | D41: Ping An | E41: 2360 | F41: Fortis | G41: Finance | H41: Insurance | I41: Belgium | J41: Europe
A42: =ROW()-6 -> 36 | B42: 2008 | C42: December | D42: Sinoma | E42: 2570 | F42: Dangote | G42: Real estate | H42: Construction | I42: Nigeria | J42: Sub-Saharan Africa
...

Sheet Dataset 1+2
A1: China Global Investment Tracker
A2: © Data compiled by The American Enterprise Institute and The Heritage Foundation. All rights reserved.
A4: Dataset 1 and 2 combined
A5: Year | B5: Month | C5: Investor/Contractor | D5: Quantity in Millions | E5: Share Size | F5: Transaction Party | G5: Sector | H5: Subsector | I5: Country | J5: Region | K5: BRI | L5: Greenfield
A6: 2005 | B6: January | C6: Chinese Academy of Sciences | D6: 1740 | F6: IBM | G6: Technology | I6: USA | J6: USA
A7: 2005 | B7: January | C7: Minmetals | D7: 500 | F7: Cubapetroleo | G7: Metals | I7: Cuba | J7: North America | L7: G
A8: 2005 | B8: January | C8: Sinohydro | D8: 100 | G8: Transport | H8: Aviation | I8: Qatar | J8: Arab Middle East and North Africa
A9: 2005 | B9: February | C9: Sinohydro | D9: 150 | F9: Oman Wastewater Services | G9: Utilities | I9: Oman | J9: Arab Middle East and North Africa
A10: 2005 | B10: February | C10: Sinohydro | D10: 370 | G10: Transport | H10: Autos | I10: Ecuador | J10: South America
A11: 2005 | B11: March | C11: MCC | D11: 670 | E11: 0.85 | F11: Highlands Pacific | G11: Metals | H11: Steel | I11: Papua New Guinea | J11: East Asia | L11: G
A12: 2005 | B12: March | C12: Sinoma | D12: 170 | F12: Riyadh Cement | G12: Real estate | H12: Construction | I12: Saudi Arabia | J12: Arab Middle East and North Africa
A13: 2005 | B13: April | C13: China National Off-shore Oil (CNOOC) | D13: 130 | E13: 0.17 | F13: MEG Energy | G13: Energy | H13: Oil | I13: Canada | J13: North America
A14: 2005 | B14: April | C14: China National Machinery Industry (Sinomach) | D14: 100 | G14: Utilities | I14: Sudan | J14: Arab Middle East and North Africa
A15: 2005 | B15: April | C15: Minmetals, MCC | D15: 240 | G15: Metals | H15: Steel | I15: Brazil | J15: South America
A16: 2005 | B16: May | C16: China National Petroleum Corp. (CNPC) | D16: 390 | F16: SONATRACH | G16: Energy | I16: Algeria | J16: Arab Middle East and North Africa
A17: 2005 | B17: June | C17: China Petroleum and Chemical (Sinopec) | D17: 120 | E17: 0.4 | F17: Synenco | G17: Energy | H17: Oil | I17: Canada | J17: North America | L17: G
A18: 2005 | B18: June | C18: China Railway Construction, China General Technology (Genertec) | D18: 1270 | F18: Cengiz and IC Ictas | G18: Transport | H18: Rail | I18: Turkey | J18: West Asia
A19: 2005 | B19: June | C19: China National Machinery Industry (Sinomach), Sinohydro | D19: 860 | G19: Energy | H19: Coal | I19: Indonesia | J19: East Asia
A20: 2005 | B20: June | C20: MCC | D20: 170 | G20: Transport | H20: Aviation | I20: Mauritania | J20: Arab Middle East and North Africa
A21: 2005 | B21: July | C21: Jiangsu Yuejin | D21: 100 | E21: 1 | F21: MG | G21: Transport | H21: Autos | I21: Britain | J21: Europe
A22: 2005 | B22: July | C22: Sinohydro | D22: 280 | G22: Energy | H22: Hydro | I22: Cambodia | J22: East Asia | L22: G
A23: 2005 | B23: July | C23: China International Trust and Investment (CITIC), Sinohydro | D23: 130 | G23: Energy | H23: Hydro | I23: Myanmar | J23: East Asia
A24: 2005 | B24: August | C24: China National Petroleum Corp. (CNPC) | D24: 4200 | E24: 0.67 | F24: PetroKazakhstan | G24: Energy | H24: Oil | I24: Kazakhstan | J24: West Asia
A25: 2005 | B25: September | C25: China National Petroleum Corp. (CNPC), China Petroleum and Chemical (Sinopec) | D25: 1420 | F25: EnCana | G25: Energy | H25: Oil | I25: Ecuador | J25: South America
A26: 2005 | B26: September | C26: China Investment Corporation (CIC), Beijing Jingdeshun | D26: 200 | G26: Energy | H26: Oil | I26: Mongolia | J26: East Asia | L26: G
A27: 2005 | B27: September | C27: China Petroleum and Chemical (Sinopec) | D27: 350 | E27: 0.45 | F27: Aker Kvaerner | G27: Chemicals | I27: Saudi Arabia | J27: Arab Middle East and North Africa
A28: 2005 | B28: October | C28: Sinosteel | D28: 140 | E28: 0.5 | F28: Midwest | G28: Metals | H28: Steel | I28: Australia | J28: Australia | L28: G
A29: 2005 | B29: October | C29: China National Chemical (ChemChina) | D29: 180 | E29: 1 | F29: Qenos | G29: Chemicals | I29: Australia | J29: Australia
A30: 2005 | B30: October | C30: China Nonferrous | D30: 330 | F30: Kazakhstan Aluminum | G30: Metals | H30: Aluminum | I30: Kazakhstan | J30: West Asia
A31: 2005 | B31: October | C31: China Communications Construction | D31: 200 | G31: Transport | H31: Autos | I31: Indonesia | J31: East Asia
A32: 2005 | B32: November | C32: China North Industries (Norinco) | D32: 120 | F32: Electricite du Laos | G32: Energy | H32: Hydro | I32: Laos | J32: East Asia
A33: 2005 | B33: November | C33: China International Trust and Investment (CITIC) | D33: 1190 | G33: Real estate | H33: Construction | I33: Venezuela | J33: South America
A34: 2005 | B34: December | C34: China National Petroleum Corp. (CNPC) | D34: 290 | E34: 0.16 | F34: Petro-Canada | G34: Energy | H34: Oil | I34: Syria | J34: Arab Middle East and North Africa
A35: 2005 | B35: December | C35: Zhejiang Holley | D35: 150 | E35: 0.75 | F35: Amata | G35: Other | H35: Industry | I35: Thailand | J35: East Asia | L35: G
A36: 2005 | B36: December | C36: China International Trust and Investment (CITIC), Aluminum Corporation of China (Chinalco) | D36: 900 | F36: South Iran Aluminum | G36: Metals | H36: Aluminum | I36: Iran | J36: West Asia
A37: 2005 | B37: December | C37: Sinoma | D37: 580 | F37: Saudi Cement | G37: Real estate | H37: Construction | I37: Saudi Arabia | J37: Arab Middle East and North Africa
A38: 2005 | B38: December | C38: China International Trust and Investment (CITIC) | D38: 430 | F38: Brazil Power | G38: Energy | H38: Coal | I38: Brazil | J38: South America
A39: 2005 | B39: December | C39: Sinohydro | D39: 210 | G39: Agriculture | I39: Algeria | J39: Arab Middle East and North Africa
A40: 2005 | B40: December | C40: China Communications Construction | D40: 210 | G40: Transport | H40: Autos | I40: Angola | J40: Sub-Saharan Africa
A41: 2005 | B41: December | C41: China National Nuclear | D41: 860 | G41: Energy | I41: Pakistan | J41: West Asia
...

Sheet FDI Stock Analysis
A1: China FDI annual analysis from Dataset 1
A2: Flows are annual sums of Quantity in Millions. Stock is a gross cumulative recorded-investment proxy, not an official FDI position measure.
A4: By destination country
A5: Annual flow (USD millions) | B5: Afghanistan | C5: Algeria | D5: Angola | E5: Antigua and Barbuda | F5: Argentina | G5: Australia | H5: Austria | I5: Azerbaijan | J5: Bahamas | K5: Bangladesh | L5: Belarus | M5: Belgium | N5: Bolivia | O5: Bosnia | P5: Botswana | Q5: Brazil | R5: Britain | S5: Brunei | T5: Bulgaria | U5: Cambodia | V5: Cameroon | W5: Canada | X5: Chad | Y5: Chile | Z5: Colombia | AA5: Congo | AB5: Croatia | AC5: Cuba | AD5: Cyprus | AE5: Czech Republic | AF5: Democratic Republic of the Congo | AG5: Denmark | AH5: Djibouti | AI5: Ecuador | AJ5: Egypt | AK5: Eritrea | AL5: Ethiopia | AM5: Finland | AN5: France | AO5: Gabon | AP5: Georgia | AQ5: Germany | AR5: Ghana | AS5: Greece | AT5: Guinea | AU5: Guinea-Bissau | AV5: Guyana | AW5: Hungary | AX5: India | AY5: Indonesia | AZ5: Iran | BA5: Iraq | BB5: Ireland | BC5: Israel | BD5: Italy | BE5: Ivory Coast | BF5: Jamaica | BG5: Japan | BH5: Jordan | BI5: Kazakhstan | BJ5: Kenya | BK5: Kuwait | BL5: Kyrgyzstan | BM5: Laos | BN5: Liberia | BO5: Luxembourg | BP5: Madagascar | BQ5: Malawi | BR5: Malaysia | BS5: Maldives | BT5: Mali | BU5: Malta | BV5: Mauritius | BW5: Mexico | BX5: Mongolia | BY5: Montenegro | BZ5: Morocco | CA5: Mozambique | CB5: Myanmar | CC5: Namibia | CD5: Nepal | CE5: Netherlands | CF5: New Zealand | CG5: Nicaragua | CH5: Niger | CI5: Nigeria | CJ5: North Korea | CK5: Norway | CL5: Oman | CM5: Pakistan | CN5: Panama | CO5: Papua New Guinea | CP5: Peru | CQ5: Philippines | CR5: Poland | CS5: Portugal | CT5: Qatar | CU5: Russian Federation | CV5: Rwanda | CW5: Samoa | CX5: Sao Tome | CY5: Saudi Arabia | CZ5: Serbia | DA5: Sierra Leone | DB5: Singapore | DC5: Slovakia | DD5: Slovenia | DE5: Solomon Islands | DF5: South Africa | DG5: South Korea | DH5: Spain | DI5: Sri Lanka | DJ5: Sudan | DK5: Suriname | DL5: Sweden | DM5: Switzerland | DN5: Syria | DO5: Taiwan | DP5: Tajikistan | DQ5: Tanzania | DR5: Thailand | DS5: Togo | DT5: Trinidad-Tobago | DU5: Tunisia | DV5: Turkey | DW5: Turkmenistan | DX5: UAE | DY5: USA | DZ5: Uganda | EA5: Ukraine | EB5: Uzbekistan | EC5: Venezuela | ED5: Vietnam | EE5: Yemen | EF5: Zambia | EG5: Zimbabwe
A6: 2005 | B6: =SUMIFS('Dataset 1'!$E$7:$E$2506,'Dataset 1'!$B$7:$B$2506,$A6,'Dataset 1'!$J$7:$J$2506,B$5) -> 0 | C6: =SUMIFS('Dataset 1'!$E$7:$E$2506,'Dataset 1'!$B$7:$B$2506,$A6,'Dataset 1'!$J$7:$J$2506,C$5) -> 0 | D6: =SUMIFS('Dataset 1'!$E$7:$E$2506,'Dataset 1'!$B$7:$B$2506,$A6,'Dataset 1'!$J$7:$J$2506,D$5) -> 0 | E6: =SUMIFS('Dataset 1'!$E$7:$E$2506,'Dataset 1'!$B$7:$B$2506,$A6,'Dataset 1'!$J$7:$J$2506,E$5) -> 0 | F6: =SUMIFS('Dataset 1'!$E$7:$E$2506,'Dataset 1'!$B$7:$B$2506,$A6,'Dataset 1'!$J$7:$J$2506,F$5) -> 0 | G6: =SUMIFS('Dataset 1'!$E$7:$E$2506,'Dataset 1'!$B$7:$B$2506,$A6,'Dataset 1'!$J$7:$J$2506,G$5) -> 320 | H6: =SUMIFS('Dataset 1'!$E$7:$E$2506,'Dataset 1'!$B$7:$B$2506,$A6,'Dataset 1'!$J$7:$J$2506,H$5) -> 0 | I6: =SUMIFS('Dataset 1'!$E$7:$E$2506,'Dataset 1'!$B$7:$B$2506,$A6,'Dataset 1'!$J$7:$J$2506,I$5) -> 0 | ... EG6: =SUMIFS('Dataset 1'!$E$7:$E$2506,'Dataset 1'!$B$7:$B$2506,$A6,'Dataset 1'!$J$7:$J$2506,EG$5) -> 0
A7: 2006 | B7: =SUMIFS('Dataset 1'!$E$7:$E$2506,'Dataset 1'!$B$7:$B$2506,$A7,'Dataset 1'!$J$7:$J$2506,B$5) -> 0 | C7: =SUMIFS('Dataset 1'!$E$7:$E$2506,'Dataset 1'!$B$7:$B$2506,$A7,'Dataset 1'!$J$7:$J$2506,C$5) -> 0 | D7: =SUMIFS('Dataset 1'!$E$7:$E$2506,'Dataset 1'!$B$7:$B$2506,$A7,'Dataset 1'!$J$7:$J$2506,D$5) -> 740 | E7: =SUMIFS('Dataset 1'!$E$7:$E$2506,'Dataset 1'!$B$7:$B$2506,$A7,'Dataset 1'!$J$7:$J$2506,E$5) -> 0 | F7: =SUMIFS('Dataset 1'!$E$7:$E$2506,'Dataset 1'!$B$7:$B$2506,$A7,'Dataset 1'!$J$7:$J$2506,F$5) -> 0 | G7: =SUMIFS('Dataset 1'!$E$7:$E$2506,'Dataset 1'!$B$7:$B$2506,$A7,'Dataset 1'!$J$7:$J$2506,G$5) -> 2920 | H7: =SUMIFS('Dataset 1'!$E$7:$E$2506,'Dataset 1'!$B$7:$B$2506,$A7,'Dataset 1'!$J$7:$J$2506,H$5) -> 0 | I7: =SUMIFS('Dataset 1'!$E$7:$E$2506,'Dataset 1'!$B$7:$B$2506,$A7,'Dataset 1'!$J$7:$J$2506,I$5) -> 0 | ... EG7: =SUMIFS('Dataset 1'!$E$7:$E$2506,'Dataset 1'!$B$7:$B$2506,$A7,'Dataset 1'!$J$7:$J$2506,EG$5) -> 0
A8: 2007 | B8: =SUMIFS('Dataset 1'!$E$7:$E$2506,'Dataset 1'!$B$7:$B$2506,$A8,'Dataset 1'!$J$7:$J$2506,B$5) -> 2520 | C8: =SUMIFS('Dataset 1'!$E$7:$E$2506,'Dataset 1'!$B$7:$B$2506,$A8,'Dataset 1'!$J$7:$J$2506,C$5) -> 0 | D8: =SUMIFS('Dataset 1'!$E$7:$E$2506,'Dataset 1'!$B$7:$B$2506,$A8,'Dataset 1'!$J$7:$J$2506,D$5) -> 0 | E8: =SUMIFS('Dataset 1'!$E$7:$E$2506,'Dataset 1'!$B$7:$B$2506,$A8,'Dataset 1'!$J$7:$J$2506,E$5) -> 0 | F8: =SUMIFS('Dataset 1'!$E$7:$E$2506,'Dataset 1'!$B$7:$B$2506,$A8,'Dataset 1'!$J$7:$J$2506,F$5) -> 0 | G8: =SUMIFS('Dataset 1'!$E$7:$E$2506,'Dataset 1'!$B$7:$B$2506,$A8,'Dataset 1'!$J$7:$J$2506,G$5) -> 430 | H8: =SUMIFS('Dataset 1'!$E$7:$E$2506,'Dataset 1'!$B$7:$B$2506,$A8,'Dataset 1'!$J$7:$J$2506,H$5) -> 0 | I8: =SUMIFS('Dataset 1'!$E$7:$E$2506,'Dataset 1'!$B$7:$B$2506,$A8,'Dataset 1'!$J$7:$J$2506,I$5) -> 0 | ... EG8: =SUMIFS('Dataset 1'!$E$7:$E$2506,'Dataset 1'!$B$7:$B$2506,$A8,'Dataset 1'!$J$7:$J$2506,EG$5) -> 100
A9: 2008 | B9: =SUMIFS('Dataset 1'!$E$7:$E$2506,'Dataset 1'!$B$7:$B$2506,$A9,'Dataset 1'!$J$7:$J$2506,B$5) -> 0 | C9: =SUMIFS('Dataset 1'!$E$7:$E$2506,'Dataset 1'!$B$7:$B$2506,$A9,'Dataset 1'!$J$7:$J$2506,C$5) -> 0 | D9: =SUMIFS('Dataset 1'!$E$7:$E$2506,'Dataset 1'!$B$7:$B$2506,$A9,'Dataset 1'!$J$7:$J$2506,D$5) -> 0 | E9: =SUMIFS('Dataset 1'!$E$7:$E$2506,'Dataset 1'!$B$7:$B$2506,$A9,'Dataset 1'!$J$7:$J$2506,E$5) -> 0 | F9: =SUMIFS('Dataset 1'!$E$7:$E$2506,'Dataset 1'!$B$7:$B$2506,$A9,'Dataset 1'!$J$7:$J$2506,F$5) -> 0 | G9: =SUMIFS('Dataset 1'!$E$7:$E$2506,'Dataset 1'!$B$7:$B$2506,$A9,'Dataset 1'!$J$7:$J$2506,G$5) -> 16250 | H9: =SUMIFS('Dataset 1'!$E$7:$E$2506,'Dataset 1'!$B$7:$B$2506,$A9,'Dataset 1'!$J$7:$J$2506,H$5) -> 0 | I9: =SUMIFS('Dataset 1'!$E$7:$E$2506,'Dataset 1'!$B$7:$B$2506,$A9,'Dataset 1'!$J$7:$J$2506,I$5) -> 0 | ... EG9: =SUMIFS('Dataset 1'!$E$7:$E$2506,'Dataset 1'!$B$7:$B$2506,$A9,'Dataset 1'!$J$7:$J$2506,EG$5) -> 0
A10: 2009 | B10: =SUMIFS('Dataset 1'!$E$7:$E$2506,'Dataset 1'!$B$7:$B$2506,$A10,'Dataset 1'!$J$7:$J$2506,B$5) -> 0 | C10: =SUMIFS('Dataset 1'!$E$7:$E$2506,'Dataset 1'!$B$7:$B$2506,$A10,'Dataset 1'!$J$7:$J$2506,C$5) -> 0 | D10: =SUMIFS('Dataset 1'!$E$7:$E$2506,'Dataset 1'!$B$7:$B$2506,$A10,'Dataset 1'!$J$7:$J$2506,D$5) -> 0 | E10: =SUMIFS('Dataset 1'!$E$7:$E$2506,'Dataset 1'!$B$7:$B$2506,$A10,'Dataset 1'!$J$7:$J$2506,E$5) -> 0 | F10: =SUMIFS('Dataset 1'!$E$7:$E$2506,'Dataset 1'!$B$7:$B$2506,$A10,'Dataset 1'!$J$7:$J$2506,F$5) -> 0 | G10: =SUMIFS('Dataset 1'!$E$7:$E$2506,'Dataset 1'!$B$7:$B$2506,$A10,'Dataset 1'!$J$7:$J$2506,G$5) -> 9130 | H10: =SUMIFS('Dataset 1'!$E$7:$E$2506,'Dataset 1'!$B$7:$B$2506,$A10,'Dataset 1'!$J$7:$J$2506,H$5) -> 140 | I10: =SUMIFS('Dataset 1'!$E$7:$E$2506,'Dataset 1'!$B$7:$B$2506,$A10,'Dataset 1'!$J$7:$J$2506,I$5) -> 0 | ... EG10: =SUMIFS('Dataset 1'!$E$7:$E$2506,'Dataset 1'!$B$7:$B$2506,$A10,'Dataset 1'!$J$7:$J$2506,EG$5) -> 0
A11: 2010 | B11: =SUMIFS('Dataset 1'!$E$7:$E$2506,'Dataset 1'!$B$7:$B$2506,$A11,'Dataset 1'!$J$7:$J$2506,B$5) -> 0 | C11: =SUMIFS('Dataset 1'!$E$7:$E$2506,'Dataset 1'!$B$7:$B$2506,$A11,'Dataset 1'!$J$7:$J$2506,C$5) -> 0 | D11: =SUMIFS('Dataset 1'!$E$7:$E$2506,'Dataset 1'!$B$7:$B$2506,$A11,'Dataset 1'!$J$7:$J$2506,D$5) -> 0 | E11: =SUMIFS('Dataset 1'!$E$7:$E$2506,'Dataset 1'!$B$7:$B$2506,$A11,'Dataset 1'!$J$7:$J$2506,E$5) -> 0 | F11: =SUMIFS('Dataset 1'!$E$7:$E$2506,'Dataset 1'!$B$7:$B$2506,$A11,'Dataset 1'!$J$7:$J$2506,F$5) -> 5680 | G11: =SUMIFS('Dataset 1'!$E$7:$E$2506,'Dataset 1'!$B$7:$B$2506,$A11,'Dataset 1'!$J$7:$J$2506,G$5) -> 3340 | H11: =SUMIFS('Dataset 1'!$E$7:$E$2506,'Dataset 1'!$B$7:$B$2506,$A11,'Dataset 1'!$J$7:$J$2506,H$5) -> 0 | I11: =SUMIFS('Dataset 1'!$E$7:$E$2506,'Dataset 1'!$B$7:$B$2506,$A11,'Dataset 1'!$J$7:$J$2506,I$5) -> 0 | ... EG11: =SUMIFS('Dataset 1'!$E$7:$E$2506,'Dataset 1'!$B$7:$B$2506,$A11,'Dataset 1'!$J$7:$J$2506,EG$5) -> 0
A12: 2011 | B12: =SUMIFS('Dataset 1'!$E$7:$E$2506,'Dataset 1'!$B$7:$B$2506,$A12,'Dataset 1'!$J$7:$J$2506,B$5) -> 400 | C12: =SUMIFS('Dataset 1'!$E$7:$E$2506,'Dataset 1'!$B$7:$B$2506,$A12,'Dataset 1'!$J$7:$J$2506,C$5) -> 0 | D12: =SUMIFS('Dataset 1'!$E$7:$E$2506,'Dataset 1'!$B$7:$B$2506,$A12,'Dataset 1'!$J$7:$J$2506,D$5) -> 2170 | E12: =SUMIFS('Dataset 1'!$E$7:$E$2506,'Dataset 1'!$B$7:$B$2506,$A12,'Dataset 1'!$J$7:$J$2506,E$5) -> 0 | F12: =SUMIFS('Dataset 1'!$E$7:$E$2506,'Dataset 1'!$B$7:$B$2506,$A12,'Dataset 1'!$J$7:$J$2506,F$5) -> 1280 | G12: =SUMIFS('Dataset 1'!$E$7:$E$2506,'Dataset 1'!$B$7:$B$2506,$A12,'Dataset 1'!$J$7:$J$2506,G$5) -> 9880 | H12: =SUMIFS('Dataset 1'!$E$7:$E$2506,'Dataset 1'!$B$7:$B$2506,$A12,'Dataset 1'!$J$7:$J$2506,H$5) -> 140 | I12: =SUMIFS('Dataset 1'!$E$7:$E$2506,'Dataset 1'!$B$7:$B$2506,$A12,'Dataset 1'!$J$7:$J$2506,I$5) -> 0 | ... EG12: =SUMIFS('Dataset 1'!$E$7:$E$2506,'Dataset 1'!$B$7:$B$2506,$A12,'Dataset 1'!$J$7:$J$2506,EG$5) -> 500
A13: 2012 | B13: =SUMIFS('Dataset 1'!$E$7:$E$2506,'Dataset 1'!$B$7:$B$2506,$A13,'Dataset 1'!$J$7:$J$2506,B$5) -> 0 | C13: =SUMIFS('Dataset 1'!$E$7:$E$2506,'Dataset 1'!$B$7:$B$2506,$A13,'Dataset 1'!$J$7:$J$2506,C$5) -> 0 | D13: =SUMIFS('Dataset 1'!$E$7:$E$2506,'Dataset 1'!$B$7:$B$2506,$A13,'Dataset 1'!$J$7:$J$2506,D$5) -> 0 | E13: =SUMIFS('Dataset 1'!$E$7:$E$2506,'Dataset 1'!$B$7:$B$2506,$A13,'Dataset 1'!$J$7:$J$2506,E$5) -> 0 | F13: =SUMIFS('Dataset 1'!$E$7:$E$2506,'Dataset 1'!$B$7:$B$2506,$A13,'Dataset 1'!$J$7:$J$2506,F$5) -> 0 | G13: =SUMIFS('Dataset 1'!$E$7:$E$2506,'Dataset 1'!$B$7:$B$2506,$A13,'Dataset 1'!$J$7:$J$2506,G$5) -> 9080 | H13: =SUMIFS('Dataset 1'!$E$7:$E$2506,'Dataset 1'!$B$7:$B$2506,$A13,'Dataset 1'!$J$7:$J$2506,H$5) -> 0 | I13: =SUMIFS('Dataset 1'!$E$7:$E$2506,'Dataset 1'!$B$7:$B$2506,$A13,'Dataset 1'!$J$7:$J$2506,I$5) -> 0 | ... EG13: =SUMIFS('Dataset 1'!$E$7:$E$2506,'Dataset 1'!$B$7:$B$2506,$A13,'Dataset 1'!$J$7:$J$2506,EG$5) -> 0
A14: 2013 | B14: =SUMIFS('Dataset 1'!$E$7:$E$2506,'Dataset 1'!$B$7:$B$2506,$A14,'Dataset 1'!$J$7:$J$2506,B$5) -> 0 | C14: =SUMIFS('Dataset 1'!$E$7:$E$2506,'Dataset 1'!$B$7:$B$2506,$A14,'Dataset 1'!$J$7:$J$2506,C$5) -> 0 | D14: =SUMIFS('Dataset 1'!$E$7:$E$2506,'Dataset 1'!$B$7:$B$2506,$A14,'Dataset 1'!$J$7:$J$2506,D$5) -> 2120 | E14: =SUMIFS('Dataset 1'!$E$7:$E$2506,'Dataset 1'!$B$7:$B$2506,$A14,'Dataset 1'!$J$7:$J$2506,E$5) -> 0 | F14: =SUMIFS('Dataset 1'!$E$7:$E$2506,'Dataset 1'!$B$7:$B$2506,$A14,'Dataset 1'!$J$7:$J$2506,F$5) -> 120 | G14: =SUMIFS('Dataset 1'!$E$7:$E$2506,'Dataset 1'!$B$7:$B$2506,$A14,'Dataset 1'!$J$7:$J$2506,G$5) -> 9060 | H14: =SUMIFS('Dataset 1'!$E$7:$E$2506,'Dataset 1'!$B$7:$B$2506,$A14,'Dataset 1'!$J$7:$J$2506,H$5) -> 0 | I14: =SUMIFS('Dataset 1'!$E$7:$E$2506,'Dataset 1'!$B$7:$B$2506,$A14,'Dataset 1'!$J$7:$J$2506,I$5) -> 0 | ... EG14: =SUMIFS('Dataset 1'!$E$7:$E$2506,'Dataset 1'!$B$7:$B$2506,$A14,'Dataset 1'!$J$7:$J$2506,EG$5) -> 0
A15: 2014 | B15: =SUMIFS('Dataset 1'!$E$7:$E$2506,'Dataset 1'!$B$7:$B$2506,$A15,'Dataset 1'!$J$7:$J$2506,B$5) -> 0 | C15: =SUMIFS('Dataset 1'!$E$7:$E$2506,'Dataset 1'!$B$7:$B$2506,$A15,'Dataset 1'!$J$7:$J$2506,C$5) -> 0 | D15: =SUMIFS('Dataset 1'!$E$7:$E$2506,'Dataset 1'!$B$7:$B$2506,$A15,'Dataset 1'!$J$7:$J$2506,D$5) -> 120 | E15: =SUMIFS('Dataset 1'!$E$7:$E$2506,'Dataset 1'!$B$7:$B$2506,$A15,'Dataset 1'!$J$7:$J$2506,E$5) -> 740 | F15: =SUMIFS('Dataset 1'!$E$7:$E$2506,'Dataset 1'!$B$7:$B$2506,$A15,'Dataset 1'!$J$7:$J$2506,F$5) -> 0 | G15: =SUMIFS('Dataset 1'!$E$7:$E$2506,'Dataset 1'!$B$7:$B$2506,$A15,'Dataset 1'!$J$7:$J$2506,G$5) -> 10060 | H15: =SUMIFS('Dataset 1'!$E$7:$E$2506,'Dataset 1'!$B$7:$B$2506,$A15,'Dataset 1'!$J$7:$J$2506,H$5) -> 0 | I15: =SUMIFS('Dataset 1'!$E$7:$E$2506,'Dataset 1'!$B$7:$B$2506,$A15,'Dataset 1'!$J$7:$J$2506,I$5) -> 0 | ... EG15: =SUMIFS('Dataset 1'!$E$7:$E$2506,'Dataset 1'!$B$7:$B$2506,$A15,'Dataset 1'!$J$7:$J$2506,EG$5) -> 250
A16: 2015 | B16: =SUMIFS('Dataset 1'!$E$7:$E$2506,'Dataset 1'!$B$7:$B$2506,$A16,'Dataset 1'!$J$7:$J$2506,B$5) -> 0 | C16: =SUMIFS('Dataset 1'!$E$7:$E$2506,'Dataset 1'!$B$7:$B$2506,$A16,'Dataset 1'!$J$7:$J$2506,C$5) -> 0 | D16: =SUMIFS('Dataset 1'!$E$7:$E$2506,'Dataset 1'!$B$7:$B$2506,$A16,'Dataset 1'!$J$7:$J$2506,D$5) -> 0 | E16: =SUMIFS('Dataset 1'!$E$7:$E$2506,'Dataset 1'!$B$7:$B$2506,$A16,'Dataset 1'!$J$7:$J$2506,E$5) -> 0 | F16: =SUMIFS('Dataset 1'!$E$7:$E$2506,'Dataset 1'!$B$7:$B$2506,$A16,'Dataset 1'!$J$7:$J$2506,F$5) -> 300 | G16: =SUMIFS('Dataset 1'!$E$7:$E$2506,'Dataset 1'!$B$7:$B$2506,$A16,'Dataset 1'!$J$7:$J$2506,G$5) -> 10990 | H16: =SUMIFS('Dataset 1'!$E$7:$E$2506,'Dataset 1'!$B$7:$B$2506,$A16,'Dataset 1'!$J$7:$J$2506,H$5) -> 0 | I16: =SUMIFS('Dataset 1'!$E$7:$E$2506,'Dataset 1'!$B$7:$B$2506,$A16,'Dataset 1'!$J$7:$J$2506,I$5) -> 0 | ... EG16: =SUMIFS('Dataset 1'!$E$7:$E$2506,'Dataset 1'!$B$7:$B$2506,$A16,'Dataset 1'!$J$7:$J$2506,EG$5) -> 0
A17: 2016 | B17: =SUMIFS('Dataset 1'!$E$7:$E$2506,'Dataset 1'!$B$7:$B$2506,$A17,'Dataset 1'!$J$7:$J$2506,B$5) -> 0 | C17: =SUMIFS('Dataset 1'!$E$7:$E$2506,'Dataset 1'!$B$7:$B$2506,$A17,'Dataset 1'!$J$7:$J$2506,C$5) -> 0 | D17: =SUMIFS('Dataset 1'!$E$7:$E$2506,'Dataset 1'!$B$7:$B$2506,$A17,'Dataset 1'!$J$7:$J$2506,D$5) -> 0 | E17: =SUMIFS('Dataset 1'!$E$7:$E$2506,'Dataset 1'!$B$7:$B$2506,$A17,'Dataset 1'!$J$7:$J$2506,E$5) -> 0 | F17: =SUMIFS('Dataset 1'!$E$7:$E$2506,'Dataset 1'!$B$7:$B$2506,$A17,'Dataset 1'!$J$7:$J$2506,F$5) -> 290 | G17: =SUMIFS('Dataset 1'!$E$7:$E$2506,'Dataset 1'!$B$7:$B$2506,$A17,'Dataset 1'!$J$7:$J$2506,G$5) -> 6840 | H17: =SUMIFS('Dataset 1'!$E$7:$E$2506,'Dataset 1'!$B$7:$B$2506,$A17,'Dataset 1'!$J$7:$J$2506,H$5) -> 0 | I17: =SUMIFS('Dataset 1'!$E$7:$E$2506,'Dataset 1'!$B$7:$B$2506,$A17,'Dataset 1'!$J$7:$J$2506,I$5) -> 0 | ... EG17: =SUMIFS('Dataset 1'!$E$7:$E$2506,'Dataset 1'!$B$7:$B$2506,$A17,'Dataset 1'!$J$7:$J$2506,EG$5) -> 0
... A26: 2025 | B26: =SUMIFS('Dataset 1'!$E$7:$E$2506,'Dataset 1'!$B$7:$B$2506,$A26,'Dataset 1'!$J$7:$J$2506,B$5) -> 0 | C26: =SUMIFS('Dataset 1'!$E$7:$E$2506,'Dataset 1'!$B$7:$B$2506,$A26,'Dataset 1'!$J$7:$J$2506,C$5) -> 530 | D26: =SUMIFS('Dataset 1'!$E$7:$E$2506,'Dataset 1'!$B$7:$B$2506,$A26,'Dataset 1'!$J$7:$J$2506,D$5) -> 0 | E26: =SUMIFS('Dataset 1'!$E$7:$E$2506,'Dataset 1'!$B$7:$B$2506,$A26,'Dataset 1'!$J$7:$J$2506,E$5) -> 0 | F26: =SUMIFS('Dataset 1'!$E$7:$E$2506,'Dataset 1'!$B$7:$B$2506,$A26,'Dataset 1'!$J$7:$J$2506,F$5) -> 380 | G26: =SUMIFS('Dataset 1'!$E$7:$E$2506,'Dataset 1'!$B$7:$B$2506,$A26,'Dataset 1'!$J$7:$J$2506,G$5) -> 680 | H26: =SUMIFS('Dataset 1'!$E$7:$E$2506,'Dataset 1'!$B$7:$B$2506,$A26,'Dataset 1'!$J$7:$J$2506,H$5) -> 0 | I26: =SUMIFS('Dataset 1'!$E$7:$E$2506,'Dataset 1'!$B$7:$B$2506,$A26,'Dataset 1'!$J$7:$J$2506,I$5) -> 0 | ... EG26: =SUMIFS('Dataset 1'!$E$7:$E$2506,'Dataset 1'!$B$7:$B$2506,$A26,'Dataset 1'!$J$7:$J$2506,EG$5) -> 360
A28: Cumulative stock proxy (USD millions) | B28: Afghanistan | C28: Algeria | D28: Angola | E28: Antigua and Barbuda | F28: Argentina | G28: Australia | H28: Austria | I28: Azerbaijan | J28: Bahamas | K28: Bangladesh | L28: Belarus | M28: Belgium | N28: Bolivia | O28: Bosnia | P28: Botswana | Q28: Brazil | R28: Britain | S28: Brunei | T28: Bulgaria | U28: Cambodia | V28: Cameroon | W28: Canada | X28: Chad | Y28: Chile | Z28: Colombia | AA28: Congo | AB28: Croatia | AC28: Cuba | AD28: Cyprus | AE28: Czech Republic | AF28: Democratic Republic of the Congo | AG28: Denmark | AH28: Djibouti | AI28: Ecuador | AJ28: Egypt | AK28: Eritrea | AL28: Ethiopia | AM28: Finland | AN28: France | AO28: Gabon | AP28: Georgia | AQ28: Germany | AR28: Ghana | AS28: Greece | AT28: Guinea | AU28: Guinea-Bissau | AV28: Guyana | AW28: Hungary | AX28: India | AY28: Indonesia | AZ28: Iran | BA28: Iraq | BB28: Ireland | BC28: Israel | BD28: Italy | BE28: Ivory Coast | BF28: Jamaica | BG28: Japan | BH28: Jordan | BI28: Kazakhstan | BJ28: Kenya | BK28: Kuwait | BL28: Kyrgyzstan | BM28: Laos | BN28: Liberia | BO28: Luxembourg | BP28: Madagascar | BQ28: Malawi | BR28: Malaysia | BS28: Maldives | BT28: Mali | BU28: Malta | BV28: Mauritius | BW28: Mexico | BX28: Mongolia | BY28: Montenegro | BZ28: Morocco | CA28: Mozambique | CB28: Myanmar | CC28: Namibia | CD28: Nepal | CE28: Netherlands | CF28: New Zealand | CG28: Nicaragua | CH28: Niger | CI28: Nigeria | CJ28: North Korea | CK28: Norway | CL28: Oman | CM28: Pakistan | CN28: Panama | CO28: Papua New Guinea | CP28: Peru | CQ28: Philippines | CR28: Poland | CS28: Portugal | CT28: Qatar | CU28: Russian Federation | CV28: Rwanda | CW28: Samoa | CX28: Sao Tome | CY28: Saudi Arabia | CZ28: Serbia | DA28: Sierra Leone | DB28: Singapore | DC28: Slovakia | DD28: Slovenia | DE28: Solomon Islands | DF28: South Africa | DG28: South Korea | DH28: Spain | DI28: Sri Lanka | DJ28: Sudan | DK28: Suriname | DL28: Sweden | DM28: Switzerland | DN28: Syria | DO28: Taiwan | DP28: Tajikistan | DQ28: Tanzania | DR28: Thailand | DS28: Togo | DT28: Trinidad-Tobago | DU28: Tunisia | DV28: Turkey | DW28: Turkmenistan | DX28: UAE | DY28: USA | DZ28: Uganda | EA28: Ukraine | EB28: Uzbekistan | EC28: Venezuela | ED28: Vietnam | EE28: Yemen | EF28: Zambia | EG28: Zimbabwe
A29: 2005 | B29: =SUMIFS('Dataset 1'!$E$7:$E$2506,'Dataset 1'!$B$7:$B$2506,"<="&$A29,'Dataset 1'!$J$7:$J$2506,B$5) -> 0 | C29: =SUMIFS('Dataset 1'!$E$7:$E$2506,'Dataset 1'!$B$7:$B$2506,"<="&$A29,'Dataset 1'!$J$7:$J$2506,C$5) -> 0 | D29: =SUMIFS('Dataset 1'!$E$7:$E$2506,'Dataset 1'!$B$7:$B$2506,"<="&$A29,'Dataset 1'!$J$7:$J$2506,D$5) -> 0 | E29: =SUMIFS('Dataset 1'!$E$7:$E$2506,'Dataset 1'!$B$7:$B$2506,"<="&$A29,'Dataset 1'!$J$7:$J$2506,E$5) -> 0 | F29: =SUMIFS('Dataset 1'!$E$7:$E$2506,'Dataset 1'!$B$7:$B$2506,"<="&$A29,'Dataset 1'!$J$7:$J$2506,F$5) -> 0 | G29: =SUMIFS('Dataset 1'!$E$7:$E$2506,'Dataset 1'!$B$7:$B$2506,"<="&$A29,'Dataset 1'!$J$7:$J$2506,G$5) -> 320 | H29: =SUMIFS('Dataset 1'!$E$7:$E$2506,'Dataset 1'!$B$7:$B$2506,"<="&$A29,'Dataset 1'!$J$7:$J$2506,H$5) -> 0 | I29: =SUMIFS('Dataset 1'!$E$7:$E$2506,'Dataset 1'!$B$7:$B$2506,"<="&$A29,'Dataset 1'!$J$7:$J$2506,I$5) -> 0 | ... EG29: =SUMIFS('Dataset 1'!$E$7:$E$2506,'Dataset 1'!$B$7:$B$2506,"<="&$A29,'Dataset 1'!$J$7:$J$2506,EG$5) -> 0
A30: 2006 | B30: =SUMIFS('Dataset 1'!$E$7:$E$2506,'Dataset 1'!$B$7:$B$2506,"<="&$A30,'Dataset 1'!$J$7:$J$2506,B$5) -> 0 | C30: =SUMIFS('Dataset 1'!$E$7:$E$2506,'Dataset 1'!$B$7:$B$2506,"<="&$A30,'Dataset 1'!$J$7:$J$2506,C$5) -> 0 | D30: =SUMIFS('Dataset 1'!$E$7:$E$2506,'Dataset 1'!$B$7:$B$2506,"<="&$A30,'Dataset 1'!$J$7:$J$2506,D$5) -> 740 | E30: =SUMIFS('Dataset 1'!$E$7:$E$2506,'Dataset 1'!$B$7:$B$2506,"<="&$A30,'Dataset 1'!$J$7:$J$2506,E$5) -> 0 | F30: =SUMIFS('Dataset 1'!$E$7:$E$2506,'Dataset 1'!$B$7:$B$2506,"<="&$A30,'Dataset 1'!$J$7:$J$2506,F$5) -> 0 | G30: =SUMIFS('Dataset 1'!$E$7:$E$2506,'Dataset 1'!$B$7:$B$2506,"<="&$A30,'Dataset 1'!$J$7:$J$2506,G$5) -> 3240 | H30: =SUMIFS('Dataset 1'!$E$7:$E$2506,'Dataset 1'!$B$7:$B$2506,"<="&$A30,'Dataset 1'!$J$7:$J$2506,H$5) -> 0 | I30: =SUMIFS('Dataset 1'!$E$7:$E$2506,'Dataset 1'!$B$7:$B$2506,"<="&$A30,'Dataset 1'!$J$7:$J$2506,I$5) -> 0 | ... EG30: =SUMIFS('Dataset 1'!$E$7:$E$2506,'Dataset 1'!$B$7:$B$2506,"<="&$A30,'Dataset 1'!$J$7:$J$2506,EG$5) -> 0
A31: 2007 | B31: =SUMIFS('Dataset 1'!$E$7:$E$2506,'Dataset 1'!$B$7:$B$2506,"<="&$A31,'Dataset 1'!$J$7:$J$2506,B$5) -> 2520 | C31: =SUMIFS('Dataset 1'!$E$7:$E$2506,'Dataset 1'!$B$7:$B$2506,"<="&$A31,'Dataset 1'!$J$7:$J$2506,C$5) -> 0 | D31: =SUMIFS('Dataset 1'!$E$7:$E$2506,'Dataset 1'!$B$7:$B$2506,"<="&$A31,'Dataset 1'!$J$7:$J$2506,D$5) -> 740 | E31: =SUMIFS('Dataset 1'!$E$7:$E$2506,'Dataset 1'!$B$7:$B$2506,"<="&$A31,'Dataset 1'!$J$7:$J$2506,E$5) -> 0 | F31: =SUMIFS('Dataset 1'!$E$7:$E$2506,'Dataset 1'!$B$7:$B$2506,"<="&$A31,'Dataset 1'!$J$7:$J$2506,F$5) -> 0 | G31: =SUMIFS('Dataset 1'!$E$7:$E$2506,'Dataset 1'!$B$7:$B$2506,"<="&$A31,'Dataset 1'!$J$7:$J$2506,G$5) -> 3670 | H31: =SUMIFS('Dataset 1'!$E$7:$E$2506,'Dataset 1'!$B$7:$B$2506,"<="&$A31,'Dataset 1'!$J$7:$J$2506,H$5) -> 0 | I31: =SUMIFS('Dataset 1'!$E$7:$E$2506,'Dataset 1'!$B$7:$B$2506,"<="&$A31,'Dataset 1'!$J$7:$J$2506,I$5) -> 0 | ... EG31: =SUMIFS('Dataset 1'!$E$7:$E$2506,'Dataset 1'!$B$7:$B$2506,"<="&$A31,'Dataset 1'!$J$7:$J$2506,EG$5) -> 100
A32: 2008 | B32: =SUMIFS('Dataset 1'!$E$7:$E$2506,'Dataset 1'!$B$7:$B$2506,"<="&$A32,'Dataset 1'!$J$7:$J$2506,B$5) -> 2520 | C32: =SUMIFS('Dataset 1'!$E$7:$E$2506,'Dataset 1'!$B$7:$B$2506,"<="&$A32,'Dataset 1'!$J$7:$J$2506,C$5) -> 0 | D32: =SUMIFS('Dataset 1'!$E$7:$E$2506,'Dataset 1'!$B$7:$B$2506,"<="&$A32,'Dataset 1'!$J$7:$J$2506,D$5) -> 740 | E32: =SUMIFS('Dataset 1'!$E$7:$E$2506,'Dataset 1'!$B$7:$B$2506,"<="&$A32,'Dataset 1'!$J$7:$J$2506,E$5) -> 0 | F32: =SUMIFS('Dataset 1'!$E$7:$E$2506,'Dataset 1'!$B$7:$B$2506,"<="&$A32,'Dataset 1'!$J$7:$J$2506,F$5) -> 0 | G32: =SUMIFS('Dataset 1'!$E$7:$E$2506,'Dataset 1'!$B$7:$B$2506,"<="&$A32,'Dataset 1'!$J$7:$J$2506,G$5) -> 19920 | H32: =SUMIFS('Dataset 1'!$E$7:$E$2506,'Dataset 1'!$B$7:$B$2506,"<="&$A32,'Dataset 1'!$J$7:$J$2506,H$5) -> 0 | I32: =SUMIFS('Dataset 1'!$E$7:$E$2506,'Dataset 1'!$B$7:$B$2506,"<="&$A32,'Dataset 1'!$J$7:$J$2506,I$5) -> 0 | ... EG32: =SUMIFS('Dataset 1'!$E$7:$E$2506,'Dataset 1'!$B$7:$B$2506,"<="&$A32,'Dataset 1'!$J$7:$J$2506,EG$5) -> 100
A33: 2009 | B33: =SUMIFS('Dataset 1'!$E$7:$E$2506,'Dataset 1'!$B$7:$B$2506,"<="&$A33,'Dataset 1'!$J$7:$J$2506,B$5) -> 2520 | C33: =SUMIFS('Dataset 1'!$E$7:$E$2506,'Dataset 1'!$B$7:$B$2506,"<="&$A33,'Dataset 1'!$J$7:$J$2506,C$5) -> 0 | D33: =SUMIFS('Dataset 1'!$E$7:$E$2506,'Dataset 1'!$B$7:$B$2506,"<="&$A33,'Dataset 1'!$J$7:$J$2506,D$5) -> 740 | E33: =SUMIFS('Dataset 1'!$E$7:$E$2506,'Dataset 1'!$B$7:$B$2506,"<="&$A33,'Dataset 1'!$J$7:$J$2506,E$5) -> 0 | F33: =SUMIFS('Dataset 1'!$E$7:$E$2506,'Dataset 1'!$B$7:$B$2506,"<="&$A33,'Dataset 1'!$J$7:$J$2506,F$5) -> 0 | G33: =SUMIFS('Dataset 1'!$E$7:$E$2506,'Dataset 1'!$B$7:$B$2506,"<="&$A33,'Dataset 1'!$J$7:$J$2506,G$5) -> 29050 | H33: =SUMIFS('Dataset 1'!$E$7:$E$2506,'Dataset 1'!$B$7:$B$2506,"<="&$A33,'Dataset 1'!$J$7:$J$2506,H$5) -> 140 | I33: =SUMIFS('Dataset 1'!$E$7:$E$2506,'Dataset 1'!$B$7:$B$2506,"<="&$A33,'Dataset 1'!$J$7:$J$2506,I$5) -> 0 | ... EG33: =SUMIFS('Dataset 1'!$E$7:$E$2506,'Dataset 1'!$B$7:$B$2506,"<="&$A33,'Dataset 1'!$J$7:$J$2506,EG$5) -> 100
A34: 2010 | B34: =SUMIFS('Dataset 1'!$E$7:$E$2506,'Dataset 1'!$B$7:$B$2506,"<="&$A34,'Dataset 1'!$J$7:$J$2506,B$5) -> 2520 | C34: =SUMIFS('Dataset 1'!$E$7:$E$2506,'Dataset 1'!$B$7:$B$2506,"<="&$A34,'Dataset 1'!$J$7:$J$2506,C$5) -> 0 | D34: =SUMIFS('Dataset 1'!$E$7:$E$2506,'Dataset 1'!$B$7:$B$2506,"<="&$A34,'Dataset 1'!$J$7:$J$2506,D$5) -> 740 | E34: =SUMIFS('Dataset 1'!$E$7:$E$2506,'Dataset 1'!$B$7:$B$2506,"<="&$A34,'Dataset 1'!$J$7:$J$2506,E$5) -> 0 | F34: =SUMIFS('Dataset 1'!$E$7:$E$2506,'Dataset 1'!$B$7:$B$2506,"<="&$A34,'Dataset 1'!$J$7:$J$2506,F$5) -> 5680 | G34: =SUMIFS('Dataset 1'!$E$7:$E$2506,'Dataset 1'!$B$7:$B$2506,"<="&$A34,'Dataset 1'!$J$7:$J$2506,G$5) -> 32390 | H34: =SUMIFS('Dataset 1'!$E$7:$E$2506,'Dataset 1'!$B$7:$B$2506,"<="&$A34,'Dataset 1'!$J$7:$J$2506,H$5) -> 140 | I34: =SUMIFS('Dataset 1'!$E$7:$E$2506,'Dataset 1'!$B$7:$B$2506,"<="&$A34,'Dataset 1'!$J$7:$J$2506,I$5) -> 0 | ... EG34: =SUMIFS('Dataset 1'!$E$7:$E$2506,'Dataset 1'!$B$7:$B$2506,"<="&$A34,'Dataset 1'!$J$7:$J$2506,EG$5) -> 100
A35: 2011 | B35: =SUMIFS('Dataset 1'!$E$7:$E$2506,'Dataset 1'!$B$7:$B$2506,"<="&$A35,'Dataset 1'!$J$7:$J$2506,B$5) -> 2920 | C35: =SUMIFS('Dataset 1'!$E$7:$E$2506,'Dataset 1'!$B$7:$B$2506,"<="&$A35,'Dataset 1'!$J$7:$J$2506,C$5) -> 0 | D35: =SUMIFS('Dataset 1'!$E$7:$E$2506,'Dataset 1'!$B$7:$B$2506,"<="&$A35,'Dataset 1'!$J$7:$J$2506,D$5) -> 2910 | E35: =SUMIFS('Dataset 1'!$E$7:$E$2506,'Dataset 1'!$B$7:$B$2506,"<="&$A35,'Dataset 1'!$J$7:$J$2506,E$5) -> 0 | F35: =SUMIFS('Dataset 1'!$E$7:$E$2506,'Dataset 1'!$B$7:$B$2506,"<="&$A35,'Dataset 1'!$J$7:$J$2506,F$5) -> 6960 | G35: =SUMIFS('Dataset 1'!$E$7:$E$2506,'Dataset 1'!$B$7:$B$2506,"<="&$A35,'Dataset 1'!$J$7:$J$2506,G$5) -> 42270 | H35: =SUMIFS('Dataset 1'!$E$7:$E$2506,'Dataset 1'!$B$7:$B$2506,"<="&$A35,'Dataset 1'!$J$7:$J$2506,H$5) -> 280 | I35: =SUMIFS('Dataset 1'!$E$7:$E$2506,'Dataset 1'!$B$7:$B$2506,"<="&$A35,'Dataset 1'!$J$7:$J$2506,I$5) -> 0 | ... EG35: =SUMIFS('Dataset 1'!$E$7:$E$2506,'Dataset 1'!$B$7:$B$2506,"<="&$A35,'Dataset 1'!$J$7:$J$2506,EG$5) -> 600
A36: 2012 | B36: =SUMIFS('Dataset 1'!$E$7:$E$2506,'Dataset 1'!$B$7:$B$2506,"<="&$A36,'Dataset 1'!$J$7:$J$2506,B$5) -> 2920 | C36: =SUMIFS('Dataset 1'!$E$7:$E$2506,'Dataset 1'!$B$7:$B$2506,"<="&$A36,'Dataset 1'!$J$7:$J$2506,C$5) -> 0 | D36: =SUMIFS('Dataset 1'!$E$7:$E$2506,'Dataset 1'!$B$7:$B$2506,"<="&$A36,'Dataset 1'!$J$7:$J$2506,D$5) -> 2910 | E36: =SUMIFS('Dataset 1'!$E$7:$E$2506,'Dataset 1'!$B$7:$B$2506,"<="&$A36,'Dataset 1'!$J$7:$J$2506,E$5) -> 0 | F36: =SUMIFS('Dataset 1'!$E$7:$E$2506,'Dataset 1'!$B$7:$B$2506,"<="&$A36,'Dataset 1'!$J$7:$J$2506,F$5) -> 6960 | G36: =SUMIFS('Dataset 1'!$E$7:$E$2506,'Dataset 1'!$B$7:$B$2506,"<="&$A36,'Dataset 1'!$J$7:$J$2506,G$5) -> 51350 | H36: =SUMIFS('Dataset 1'!$E$7:$E$2506,'Dataset 1'!$B$7:$B$2506,"<="&$A36,'Dataset 1'!$J$7:$J$2506,H$5) -> 280 | I36: =SUMIFS('Dataset 1'!$E$7:$E$2506,'Dataset 1'!$B$7:$B$2506,"<="&$A36,'Dataset 1'!$J$7:$J$2506,I$5) -> 0 | ... EG36: =SUMIFS('Dataset 1'!$E$7:$E$2506,'Dataset 1'!$B$7:$B$2506,"<="&$A36,'Dataset 1'!$J$7:$J$2506,EG$5) -> 600
A37: 2013 | B37: =SUMIFS('Dataset 1'!$E$7:$E$2506,'Dataset 1'!$B$7:$B$2506,"<="&$A37,'Dataset 1'!$J$7:$J$2506,B$5) -> 2920 | C37: =SUMIFS('Dataset 1'!$E$7:$E$2506,'Dataset 1'!$B$7:$B$2506,"<="&$A37,'Dataset 1'!$J$7:$J$2506,C$5) -> 0 | D37: =SUMIFS('Dataset 1'!$E$7:$E$2506,'Dataset 1'!$B$7:$B$2506,"<="&$A37,'Dataset 1'!$J$7:$J$2506,D$5) -> 5030 | E37: =SUMIFS('Dataset 1'!$E$7:$E$2506,'Dataset 1'!$B$7:$B$2506,"<="&$A37,'Dataset 1'!$J$7:$J$2506,E$5) -> 0 | F37: =SUMIFS('Dataset 1'!$E$7:$E$2506,'Dataset 1'!$B$7:$B$2506,"<="&$A37,'Dataset 1'!$J$7:$J$2506,F$5) -> 7080 | G37: =SUMIFS('Dataset 1'!$E$7:$E$2506,'Dataset 1'!$B$7:$B$2506,"<="&$A37,'Dataset 1'!$J$7:$J$2506,G$5) -> 60410 | H37: =SUMIFS('Dataset 1'!$E$7:$E$2506,'Dataset 1'!$B$7:$B$2506,"<="&$A37,'Dataset 1'!$J$7:$J$2506,H$5) -> 280 | I37: =SUMIFS('Dataset 1'!$E$7:$E$2506,'Dataset 1'!$B$7:$B$2506,"<="&$A37,'Dataset 1'!$J$7:$J$2506,I$5) -> 0 | ... EG37: =SUMIFS('Dataset 1'!$E$7:$E$2506,'Dataset 1'!$B$7:$B$2506,"<="&$A37,'Dataset 1'!$J$7:$J$2506,EG$5) -> 600
A38: 2014 | B38: =SUMIFS('Dataset 1'!$E$7:$E$2506,'Dataset 1'!$B$7:$B$2506,"<="&$A38,'Dataset 1'!$J$7:$J$2506,B$5) -> 2920 | C38: =SUMIFS('Dataset 1'!$E$7:$E$2506,'Dataset 1'!$B$7:$B$2506,"<="&$A38,'Dataset 1'!$J$7:$J$2506,C$5) -> 0 | D38: =SUMIFS('Dataset 1'!$E$7:$E$2506,'Dataset 1'!$B$7:$B$2506,"<="&$A38,'Dataset 1'!$J$7:$J$2506,D$5) -> 5150 | E38: =SUMIFS('Dataset 1'!$E$7:$E$2506,'Dataset 1'!$B$7:$B$2506,"<="&$A38,'Dataset 1'!$J$7:$J$2506,E$5) -> 740 | F38: =SUMIFS('Dataset 1'!$E$7:$E$2506,'Dataset 1'!$B$7:$B$2506,"<="&$A38,'Dataset 1'!$J$7:$J$2506,F$5) -> 7080 | G38: =SUMIFS('Dataset 1'!$E$7:$E$2506,'Dataset 1'!$B$7:$B$2506,"<="&$A38,'Dataset 1'!$J$7:$J$2506,G$5) -> 70470 | H38: =SUMIFS('Dataset 1'!$E$7:$E$2506,'Dataset 1'!$B$7:$B$2506,"<="&$A38,'Dataset 1'!$J$7:$J$2506,H$5) -> 280 | I38: =SUMIFS('Dataset 1'!$E$7:$E$2506,'Dataset 1'!$B$7:$B$2506,"<="&$A38,'Dataset 1'!$J$7:$J$2506,I$5) -> 0 | ... EG38: =SUMIFS('Dataset 1'!$E$7:$E$2506,'Dataset 1'!$B$7:$B$2506,"<="&$A38,'Dataset 1'!$J$7:$J$2506,EG$5) -> 850
A39: 2015 | B39: =SUMIFS('Dataset 1'!$E$7:$E$2506,'Dataset 1'!$B$7:$B$2506,"<="&$A39,'Dataset 1'!$J$7:$J$2506,B$5) -> 2920 | C39: =SUMIFS('Dataset 1'!$E$7:$E$2506,'Dataset 1'!$B$7:$B$2506,"<="&$A39,'Dataset 1'!$J$7:$J$2506,C$5) -> 0 | D39: =SUMIFS('Dataset 1'!$E$7:$E$2506,'Dataset 1'!$B$7:$B$2506,"<="&$A39,'Dataset 1'!$J$7:$J$2506,D$5) -> 5150 | E39: =SUMIFS('Dataset 1'!$E$7:$E$2506,'Dataset 1'!$B$7:$B$2506,"<="&$A39,'Dataset 1'!$J$7:$J$2506,E$5) -> 740 | F39: =SUMIFS('Dataset 1'!$E$7:$E$2506,'Dataset 1'!$B$7:$B$2506,"<="&$A39,'Dataset 1'!$J$7:$J$2506,F$5) -> 7380 | G39: =SUMIFS('Dataset 1'!$E$7:$E$2506,'Dataset 1'!$B$7:$B$2506,"<="&$A39,'Dataset 1'!$J$7:$J$2506,G$5) -> 81460 | H39: =SUMIFS('Dataset 1'!$E$7:$E$2506,'Dataset 1'!$B$7:$B$2506,"<="&$A39,'Dataset 1'!$J$7:$J$2506,H$5) -> 280 | I39: =SUMIFS('Dataset 1'!$E$7:$E$2506,'Dataset 1'!$B$7:$B$2506,"<="&$A39,'Dataset 1'!$J$7:$J$2506,I$5) -> 0 | ... EG39: =SUMIFS('Dataset 1'!$E$7:$E$2506,'Dataset 1'!$B$7:$B$2506,"<="&$A39,'Dataset 1'!$J$7:$J$2506,EG$5) -> 850
A40: 2016 | B40: =SUMIFS('Dataset 1'!$E$7:$E$2506,'Dataset 1'!$B$7:$B$2506,"<="&$A40,'Dataset 1'!$J$7:$J$2506,B$5) -> 2920 | C40: =SUMIFS('Dataset 1'!$E$7:$E$2506,'Dataset 1'!$B$7:$B$2506,"<="&$A40,'Dataset 1'!$J$7:$J$2506,C$5) -> 0 | D40: =SUMIFS('Dataset 1'!$E$7:$E$2506,'Dataset 1'!$B$7:$B$2506,"<="&$A40,'Dataset 1'!$J$7:$J$2506,D$5) -> 5150 | E40: =SUMIFS('Dataset 1'!$E$7:$E$2506,'Dataset 1'!$B$7:$B$2506,"<="&$A40,'Dataset 1'!$J$7:$J$2506,E$5) -> 740 | F40: =SUMIFS('Dataset 1'!$E$7:$E$2506,'Dataset 1'!$B$7:$B$2506,"<="&$A40,'Dataset 1'!$J$7:$J$2506,F$5) -> 7670 | G40: =SUMIFS('Dataset 1'!$E$7:$E$2506,'Dataset 1'!$B$7:$B$2506,"<="&$A40,'Dataset 1'!$J$7:$J$2506,G$5) -> 88300 | H40: =SUMIFS('Dataset 1'!$E$7:$E$2506,'Dataset 1'!$B$7:$B$2506,"<="&$A40,'Dataset 1'!$J$7:$J$2506,H$5) -> 280 | I40: =SUMIFS('Dataset 1'!$E$7:$E$2506,'Dataset 1'!$B$7:$B$2506,"<="&$A40,'Dataset 1'!$J$7:$J$2506,I$5) -> 0 | ... EG40: =SUMIFS('Dataset 1'!$E$7:$E$2506,'Dataset 1'!$B$7:$B$2506,"<="&$A40,'Dataset 1'!$J$7:$J$2506,EG$5) -> 850
... A49: 2025 | B49: =SUMIFS('Dataset 1'!$E$7:$E$2506,'Dataset 1'!$B$7:$B$2506,"<="&$A49,'Dataset 1'!$J$7:$J$2506,B$5) -> 3070 | C49: =SUMIFS('Dataset 1'!$E$7:$E$2506,'Dataset 1'!$B$7:$B$2506,"<="&$A49,'Dataset 1'!$J$7:$J$2506,C$5) -> 960 | D49: =SUMIFS('Dataset 1'!$E$7:$E$2506,'Dataset 1'!$B$7:$B$2506,"<="&$A49,'Dataset 1'!$J$7:$J$2506,D$5) -> 5520 | E49: =SUMIFS('Dataset 1'!$E$7:$E$2506,'Dataset 1'!$B$7:$B$2506,"<="&$A49,'Dataset 1'!$J$7:$J$2506,E$5) -> 740 | F49: =SUMIFS('Dataset 1'!$E$7:$E$2506,'Dataset 1'!$B$7:$B$2506,"<="&$A49,'Dataset 1'!$J$7:$J$2506,F$5) -> 13530 | G49: =SUMIFS('Dataset 1'!$E$7:$E$2506,'Dataset 1'!$B$7:$B$2506,"<="&$A49,'Dataset 1'!$J$7:$J$2506,G$5) -> 108180 | H49: =SUMIFS('Dataset 1'!$E$7:$E$2506,'Dataset 1'!$B$7:$B$2506,"<="&$A49,'Dataset 1'!$J$7:$J$2506,H$5) -> 1110 | I49: =SUMIFS('Dataset 1'!$E$7:$E$2506,'Dataset 1'!$B$7:$B$2506,"<="&$A49,'Dataset 1'!$J$7:$J$2506,I$5) -> 270 | ... EG49: =SUMIFS('Dataset 1'!$E$7:$E$2506,'Dataset 1'!$B$7:$B$2506,"<="&$A49,'Dataset 1'!$J$7:$J$2506,EG$5) -> 4710
A51: By investment sector
A52: Annual flow (USD millions) | B52: Agriculture | C52: Chemicals | D52: Energy | E52: Entertainment | F52: Finance | G52: Health | H52: Logistics | I52: Metals | J52: Other | K52: Real estate | L52: Technology | M52: Tourism | N52: Transport | O52: Utilities
A53: 2005 | B53: =SUMIFS('Dataset 1'!$E$7:$E$2506,'Dataset 1'!$B$7:$B$2506,$A53,'Dataset 1'!$H$7:$H$2506,B$52) -> 0 | C53: =SUMIFS('Dataset 1'!$E$7:$E$2506,'Dataset 1'!$B$7:$B$2506,$A53,'Dataset 1'!$H$7:$H$2506,C$52) -> 180 | D53: =SUMIFS('Dataset 1'!$E$7:$E$2506,'Dataset 1'!$B$7:$B$2506,$A53,'Dataset 1'!$H$7:$H$2506,D$52) -> 6640 | E53: =SUMIFS('Dataset 1'!$E$7:$E$2506,'Dataset 1'!$B$7:$B$2506,$A53,'Dataset 1'!$H$7:$H$2506,E$52) -> 0 | F53: =SUMIFS('Dataset 1'!$E$7:$E$2506,'Dataset 1'!$B$7:$B$2506,$A53,'Dataset 1'!$H$7:$H$2506,F$52) -> 0 | G53: =SUMIFS('Dataset 1'!$E$7:$E$2506,'Dataset 1'!$B$7:$B$2506,$A53,'Dataset 1'!$H$7:$H$2506,G$52) -> 0 | H53: =SUMIFS('Dataset 1'!$E$7:$E$2506,'Dataset 1'!$B$7:$B$2506,$A53,'Dataset 1'!$H$7:$H$2506,H$52) -> 0 | I53: =SUMIFS('Dataset 1'!$E$7:$E$2506,'Dataset 1'!$B$7:$B$2506,$A53,'Dataset 1'!$H$7:$H$2506,I$52) -> 1310 | ... O53: =SUMIFS('Dataset 1'!$E$7:$E$2506,'Dataset 1'!$B$7:$B$2506,$A53,'Dataset 1'!$H$7:$H$2506,O$52) -> 0
A54: 2006 | B54: =SUMIFS('Dataset 1'!$E$7:$E$2506,'Dataset 1'!$B$7:$B$2506,$A54,'Dataset 1'!$H$7:$H$2506,B$52) -> 480 | C54: =SUMIFS('Dataset 1'!$E$7:$E$2506,'Dataset 1'!$B$7:$B$2506,$A54,'Dataset 1'!$H$7:$H$2506,C$52) -> 0 | D54: =SUMIFS('Dataset 1'!$E$7:$E$2506,'Dataset 1'!$B$7:$B$2506,$A54,'Dataset 1'!$H$7:$H$2506,D$52) -> 10170 | E54: =SUMIFS('Dataset 1'!$E$7:$E$2506,'Dataset 1'!$B$7:$B$2506,$A54,'Dataset 1'!$H$7:$H$2506,E$52) -> 0 | F54: =SUMIFS('Dataset 1'!$E$7:$E$2506,'Dataset 1'!$B$7:$B$2506,$A54,'Dataset 1'!$H$7:$H$2506,F$52) -> 100 | G54: =SUMIFS('Dataset 1'!$E$7:$E$2506,'Dataset 1'!$B$7:$B$2506,$A54,'Dataset 1'!$H$7:$H$2506,G$52) -> 0 | H54: =SUMIFS('Dataset 1'!$E$7:$E$2506,'Dataset 1'!$B$7:$B$2506,$A54,'Dataset 1'!$H$7:$H$2506,H$52) -> 0 | I54: =SUMIFS('Dataset 1'!$E$7:$E$2506,'Dataset 1'!$B$7:$B$2506,$A54,'Dataset 1'!$H$7:$H$2506,I$52) -> 6470 | ... O54: =SUMIFS('Dataset 1'!$E$7:$E$2506,'Dataset 1'!$B$7:$B$2506,$A54,'Dataset 1'!$H$7:$H$2506,O$52) -> 0
A55: 2007 | B55: =SUMIFS('Dataset 1'!$E$7:$E$2506,'Dataset 1'!$B$7:$B$2506,$A55,'Dataset 1'!$H$7:$H$2506,B$52) -> 0 | C55: =SUMIFS('Dataset 1'!$E$7:$E$2506,'Dataset 1'!$B$7:$B$2506,$A55,'Dataset 1'!$H$7:$H$2506,C$52) -> 700 | D55: =SUMIFS('Dataset 1'!$E$7:$E$2506,'Dataset 1'!$B$7:$B$2506,$A55,'Dataset 1'!$H$7:$H$2506,D$52) -> 3200 | E55: =SUMIFS('Dataset 1'!$E$7:$E$2506,'Dataset 1'!$B$7:$B$2506,$A55,'Dataset 1'!$H$7:$H$2506,E$52) -> 0 | F55: =SUMIFS('Dataset 1'!$E$7:$E$2506,'Dataset 1'!$B$7:$B$2506,$A55,'Dataset 1'!$H$7:$H$2506,F$52) -> 19460 | G55: =SUMIFS('Dataset 1'!$E$7:$E$2506,'Dataset 1'!$B$7:$B$2506,$A55,'Dataset 1'!$H$7:$H$2506,G$52) -> 0 | H55: =SUMIFS('Dataset 1'!$E$7:$E$2506,'Dataset 1'!$B$7:$B$2506,$A55,'Dataset 1'!$H$7:$H$2506,H$52) -> 150 | I55: =SUMIFS('Dataset 1'!$E$7:$E$2506,'Dataset 1'!$B$7:$B$2506,$A55,'Dataset 1'!$H$7:$H$2506,I$52) -> 5930 | ... O55: =SUMIFS('Dataset 1'!$E$7:$E$2506,'Dataset 1'!$B$7:$B$2506,$A55,'Dataset 1'!$H$7:$H$2506,O$52) -> 0
